Workbook

Sheet 모듈 별 견적
C2: PROTO INC. Software Development | K2: 일본 본사 | M2: 회사 명 : 株式会社ｐｒｏｔｏ 사업자 번호 : 7011101083414 대표자 : 金 知賢 / 金 書浩 주소 : 東京都新宿区新宿2-11-7第33宮庭ビル5F 연락처 : +81 50-5539-8928
D3: (주)테이크원컴퍼니 귀하 | K3: 한국 지사 | M3: 회사 명 : 주식회사 투스페이스 사업자 번호 : 714-88-02482 대표자 : 김서호 주소 : 서울특별시 강남구 선릉로145길 13, 4F 연락처 : +82 70-7174-2181
D4: 아래와 같이 견적합니다 | K4: 주요 사업 | M4: SW 개발 / IT 서비스 운영 / 종합 광고 대행
D6: 견적일자 | E6: =TODAY() -> 45870 | K6: 세일즈 담당자 | M6: B2B세일즈팀 김성훈 매니저
D7: 유효기간 | E7: =(E6+F7-1) -> 45899 | F7: 30 | K7: 연락처 | M7: +82 10-4972-5418
K8: 이메일 주소 | M8: dante@proto.co.jp
B10: 최종 견적가 | J10: =sum(J11:J13)-J14 -> 370000000 | N10: =J10*10% -> 37000000
E11: 직접 노무비 (업무처리비) | J11: =sum(L27+L40+L50) -> 255044700 | N11: =J11*10% -> 25504470
E12: 제경비 | H12: 0.25 | J12: =J11*H12 -> 63761175 | N12: =J12*10% -> 6376117.5
E13: 기술료 (수익률) | H13: 0.2 | J13: =SUM(J11:J12)*H13 -> 63761175 | N13: =J13*10% -> 6376117.5
E14: 파트너 할인 | J14: 12567050 | N14: =J14*10% -> 1256705
E16: 최종 결과물 | H16: 결과물 | I16: OTT 모바일 앱 (Android, iOS) 및 백엔드, 어드민 사이트, 랜딩페이지 | L16: 결제 방법 | M16: 선금 40% / 중도금 30% / 잔금 30%
H17: 개발 기간 | I17: 2025.05.01 ~ 2025.08.31 | L17: 청구 방법 | M17: 전자세금계산서 발행
B19: 세부 견적 기준
B21: NO | D21: 중분류 | E21: 주요 기능 | H21: 예상 시작일 | I21: 예상 종료일 | J21: 월 비용 | K21: 소요일 | L21: 총합 | N21: _x0008_부가세
B23: 프로젝트 관리 및 기획 (1.5M/M 투입 기준) | L23: =sum(L27) -> 28271700 | N23: =L23*10% -> 2827170
B24: 1 | D24: 프로젝트 관리 | E24: 프로젝트 세팅 | H24: 45778 | I24: 45793 | J24: ='SET 투입 인력 및 비용'!J5 -> 15000000 | K24: 15 | L24: =J24*3.33%*K24 -> 7492500 | N24: =L24*10% -> 749250
B25: =B24+1 -> 2 | E25: 프로젝트 매니지먼트 | H25: 45778 | I25: 45898 | J25: ='SET 투입 인력 및 비용'!J5 -> 15000000 | K25: 79 | L25: =J25*3.33%*K25*0.4 -> 15784200 | N25: =L25*10% -> 1578420
B26: =B25+1 -> 3 | E26: 서비스 기획 | H26: 45778 | I26: 45808 | J26: ='SET 투입 인력 및 비용'!J$6 -> 7500000 | K26: 20 | L26: =J26*3.33%*K26 -> 4995000 | N26: =L26*10% -> 499500
D27: 소계 | K27: =sum(K24:K26) -> 114 | L27: =sum(L24:L26) -> 28271700 | N27: =L27*10% -> 2827170
B29: 제공 기획안에 대한 예상 견적 | L29: =sum(L30:L39) -> 160839000 | N29: =L29*10% -> 16083900
B30: 3 | D30: UIUX 디자인 | E30: - OTT 서비스 앱 화면 L 영상 플레이 화면 L 배너 영역 L 작품 상세정보 영역 L 에피소드 목록 L 마이페이지 L 조회수 노출 - 어드민 페이지 - 랜딩 페이지 | H30: 45778 | I30: =WORKDAY(H30, (K30) - 1, 'SET 주요 휴일'!$B$2:$B$26) -> 45838 | J30: ='SET 투입 인력 및 비용'!J$7 -> 7500000 | K30: 40 | L30: =J30*K30*3.33% -> 9990000 | N30: =L30*10% -> 999000
B31: =B30+1 -> 4 | D31: 영상 관리 | E31: - 영상 플레이어 기능 - 영상 설정 (자막, 배속, 화질, pip, 상세) - 플렛폼 로고 삽입 - 녹화 제한 기능 | H31: 45778 | I31: =WORKDAY(H31, (K31) - 1, 'SET 주요 휴일'!$B$2:$B$26) -> 45810 | J31: =SUM('SET 투입 인력 및 비용'!J$9, 'SET 투입 인력 및 비용'!J$11) -> 30000000 | K31: 20 | L31: =J31*3.33%*K31 -> 19980000 | N31: =L31*10% -> 1998000
B32: =B31+1 -> 5 | D32: 회차 관리 | E32: - 다음 회차 자동 재생 - 결제창 표시 및 자동 결제 기능 | H32: =WORKDAY(H43, (K43), 'SET 주요 휴일'!$B$2:$B$26) -> 45817 | I32: =WORKDAY(H32, (K32) - 1, 'SET 주요 휴일'!$B$2:$B$26) -> 45832 | J32: =SUM('SET 투입 인력 및 비용'!J$9, 'SET 투입 인력 및 비용'!J$11) -> 30000000 | K32: 12 | L32: =J32*3.33%*K32 -> 11988000 | N32: =L32*10% -> 1198800
B33: =B32+1 -> 6 | D33: 인터렉션 & 커뮤니티 | E33: - 좋아요 기능 - 외부 공유 기능 - 알림 기능 - 인터렉티브 기능 | H33: =WORKDAY(H45, (K45), 'SET 주요 휴일'!$B$2:$B$26) -> 45876 | I33: =WORKDAY(H33, (K33) - 1, 'SET 주요 휴일'!$B$2:$B$26) -> 45897 | J33: =SUM('SET 투입 인력 및 비용'!J$10, 'SET 투입 인력 및 비용'!J$12) -> 18000000 | K33: 12 | L33: =J33*3.33%*K33 -> 7192800 | N33: =L33*10% -> 719280
B34: =B33+1 -> 7 | D34: 광고 기능 | E34: - 영상 중간 광고 기능 - 배너 광고 기능 - 영상 상단 PPL 상품 기능 - 커머스 바로가기 링크 기능 - 인앱 광고 시청 후 리워드 기능 | H34: =WORKDAY(H44, (K44), 'SET 주요 휴일'!$B$2:$B$26) -> 45839 | I34: =WORKDAY(H34, (K34) - 1, 'SET 주요 휴일'!$B$2:$B$26) -> 45891 | J34: =SUM('SET 투입 인력 및 비용'!J$9, 'SET 투입 인력 및 비용'!J$11) -> 30000000 | K34: 34 | L34: =J34*3.33%*K34 -> 33966000 | N34: =L34*10% -> 3396600
B35: =B34+1 -> 8 | D35: 결제 관리 | E35: - 결제 서비스 관리 - 작품당 구독 모델 - 일회성 충전식 구독 모델 - 결제 후 보상 (ex: 추가 콘텐츠, 서비스 코인 등) | H35: =WORKDAY(H46, (K46), 'SET 주요 휴일'!$B$2:$B$26) -> 45821 | I35: =WORKDAY(H35, (K35) - 1, 'SET 주요 휴일'!$B$2:$B$26) -> 45863 | J35: =SUM('SET 투입 인력 및 비용'!J$10, 'SET 투입 인력 및 비용'!J$11) -> 24000000 | K35: 30 | L35: =J35*3.33%*K35 -> 23976000 | N35: =L35*10% -> 2397600
B36: =B35+1 -> 9 | D36: AI 활용 기능 | E36: - 다국어 자막 기능(실시간 불가) | H36: =WORKDAY(H34, (K34), 'SET 주요 휴일'!$B$2:$B$26) -> 45894 | I36: =WORKDAY(H36, (K36) - 1, 'SET 주요 휴일'!$B$2:$B$26) -> 45898 | J36: =SUM('SET 투입 인력 및 비용'!J$9, 'SET 투입 인력 및 비용'!J$11) -> 30000000 | K36: 5 | L36: =J36*3.33%*K36 -> 4995000 | N36: =L36*10% -> 499500
B37: =B36+1 -> 10 | D37: 서버 관리 | E37: - DRM 서버 구축 - CDN 최적화 - 트래픽 급증 대응 기능 - 로그 분석 & 데이터 수집(조회수, 좋아요 등등) | H37: 45839 | I37: =WORKDAY(H37, (K37) - 1, 'SET 주요 휴일'!$B$2:$B$26) -> 45898 | J37: =SUM('SET 투입 인력 및 비용'!J$11 : 'SET 투입 인력 및 비용'!J$12) -> 24000000 | K37: 39 | L37: =J37*3.33%*K37 -> 31168800 | N37: =L37*10% -> 3116880
B38: =B37+1 -> 11 | D38: 유저 관리 | E38: - SNS 로그인 (구글, 애플, 카카오로그인 기준) | H38: 45778 | I38: =WORKDAY(H38, (K38) - 1, 'SET 주요 휴일'!$B$2:$B$26) -> 45786 | J38: =SUM('SET 투입 인력 및 비용'!J$10, 'SET 투입 인력 및 비용'!J$12) -> 18000000 | K38: 4 | L38: =J38*3.33%*K38 -> 2397600 | N38: =L38*10% -> 239760
B39: =B38+1 -> 12 | D39: 베포 관리 | E39: - 베포 및 심사 준비 - 심사 대응 | H39: 45868 | I39: =WORKDAY(H39, (K39) - 1, 'SET 주요 휴일'!$B$2:$B$26) -> 45898 | J39: 24000000 | K39: 19 | L39: =J39*3.33%*K39 -> 15184800 | N39: =L39*10% -> 1518480
D40: 소계 | K40: =SUM(K30:K38) -> 196 | L40: =sum(L30:L39) -> 160839000 | N40: =L40*10% -> 16083900
B42: 누락 기능에 대한 예상 견적 | L42: =sum(L43:L49) -> 65934000 | N42: =L42*10% -> 6593400
B43: 12 | D43: 영상 관리 | E43: - 시청한 영상 기록 표시 | H43: =WORKDAY(H31, (K31), 'SET 주요 휴일'!$B$2:$B$26) -> 45811 | I43: =WORKDAY(H43, (K43) - 1, 'SET 주요 휴일'!$B$2:$B$26) -> 45814 | J43: =SUM('SET 투입 인력 및 비용'!J$9, 'SET 투입 인력 및 비용'!J$11) -> 30000000 | K43: 4 | L43: =J43*3.33%*K43 -> 3996000 | N43: =L43*10% -> 399600
B44: =B43+1 -> 13 | D44: 회차 관리 | E44: - 시청한 회차 기록 기능 | H44: =WORKDAY(H32, (K32), 'SET 주요 휴일'!$B$2:$B$26) -> 45833 | I44: =WORKDAY(I32, (K44) - 1, 'SET 주요 휴일'!$B$2:$B$26) -> 45835 | J44: =SUM('SET 투입 인력 및 비용'!J$9, 'SET 투입 인력 및 비용'!J$11) -> 30000000 | K44: 4 | L44: =J44*3.33%*K44 -> 3996000 | N44: =L44*10% -> 399600
B45: =B44+1 -> 14 | D45: 결제 관리 | E45: - 서비스 코인 관리 기능 | H45: =WORKDAY(H35, (K35), 'SET 주요 휴일'!$B$2:$B$26) -> 45866 | I45: =WORKDAY(H45, (K45) - 1, 'SET 주요 휴일'!$B$2:$B$26) -> 45875 | J45: =SUM('SET 투입 인력 및 비용'!J$10, 'SET 투입 인력 및 비용'!J$11) -> 24000000 | K45: 8 | L45: =J45*3.33%*K45 -> 6393600 | N45: =L45*10% -> 639360
B46: =B45+1 -> 15 | D46: 유저 관리 | E46: - 회원 데이터 관리 - 마이페이지 - 회원 설정 L 닉네임 수정 L 로그아웃 L 회원탈퇴 | H46: =WORKDAY(H38, (K38), 'SET 주요 휴일'!$B$2:$B$26) -> 45789 | I46: =WORKDAY(H46, (K46) - 1, 'SET 주요 휴일'!$B$2:$B$26) -> 45820 | J46: =SUM('SET 투입 인력 및 비용'!J$10, 'SET 투입 인력 및 비용'!J$12) -> 18000000 | K46: 24 | L46: =J46*3.33%*K46 -> 14385600 | N46: =L46*10% -> 1438560
B47: =B46+1 -> 16 | D47: 기타 기능 | E47: - 랜딩 페이지 제작 - 검색 기능 - 작품 리스트, 에피소드 리스트 - 문의 관리 - 다국어 기능 - 권한 관리 | H47: =WORKDAY(H46, (K46), 'SET 주요 휴일'!$B$2:$B$26) -> 45821 | I47: =WORKDAY(H47, (K47) - 1, 'SET 주요 휴일'!$B$2:$B$26) -> 45854 | J47: 24000000 | K47: 24 | L47: =J47*3.33%*K47 -> 19180800 | N47: =L47*10% -> 1918080
B48: =B47+1 -> 17 | D48: 어드민 페이지 | E48: - 영상 등록 - 영상 광고 관리 - 배너 광고 관리 - 회원 관리 - 결제 이력 관리 - 문의 관리 | H48: 45809 | I48: =WORKDAY(H48, (K48) - 1, 'SET 주요 휴일'!$B$2:$B$26) -> 45848 | J48: =SUM('SET 투입 인력 및 비용'!J$8, 'SET 투입 인력 및 비용'!J$12) -> 15000000 | K48: 30 | L48: =J48*3.33%*K48 -> 14985000 | N48: =L48*10% -> 1498500
B49: =B48+1 -> 18 | D49: 랜딩 페이지 | E49: - 홈페이지 제작 | H49: 45848 | I49: =WORKDAY(H49, (K49) - 1, 'SET 주요 휴일'!$B$2:$B$26) -> 45869 | J49: =SUM('SET 투입 인력 및 비용'!J$8) -> 6000000 | K49: 15 | L49: =J49*3.33%*K49 -> 2997000 | N49: =L49*10% -> 299700
...

Sheet MM 별 견적
C2: PROTO INC. Software Development | K2: 일본 본사 | M2: 회사 명 : 株式会社ｐｒｏｔｏ 사업자 번호 : 7011101083414 대표자 : 金 知賢 / 金 書浩 주소 : 東京都新宿区新宿2-11-7第33宮庭ビル5F 연락처 : +81 50-5539-8928
D3: (주)테이크원컴퍼니 귀하 | K3: 한국 지사 | M3: 회사 명 : 주식회사 투스페이스 사업자 번호 : 714-88-02482 대표자 : 김서호 주소 : 서울특별시 강남구 선릉로145길 13, 4F 연락처 : +82 70-7174-2181
D4: 아래와 같이 견적합니다 | K4: 주요 사업 | M4: SW 개발 / IT 서비스 운영 / 종합 광고 대행
D6: 견적일자 | E6: =TODAY() -> 45870 | K6: 세일즈 담당자 | M6: B2B세일즈팀 김성훈 매니저
D7: 유효기간 | E7: =(E6+F7-1) -> 45899 | F7: 30 | K7: 연락처 | M7: +82 10-4972-5418
K8: 이메일 주소 | M8: dante@proto.co.jp
B10: 최종 견적가 | J10: =sum(J11:J13)-J14 -> 370000000 | N10: =J10*10% -> 37000000
E11: 직접 노무비 (업무처리비) | J11: =sum(L30) -> 254100000 | N11: =J11*10% -> 25410000
E12: 제경비 | H12: 0.25 | J12: =J11*H12 -> 63525000 | N12: =J12*10% -> 6352500
E13: 기술료 (수익률) | H13: 0.2 | J13: =SUM(J11:J12)*H13 -> 63525000 | N13: =J13*10% -> 6352500
E14: 파트너 할인 | J14: 11150000 | N14: =J14*10% -> 1115000
E16: 최종 결과물 | H16: 결과물 | I16: OTT 모바일 앱 (Android, iOS) 및 백엔드, 어드민 사이트, 랜딩페이지 | L16: 결제 방법 | M16: 선금 40% / 중도금 30% / 잔금 30%
H17: 개발 기간 | I17: 2025.05.01 ~ 2025.08.31 | L17: 청구 방법 | M17: 전자세금계산서 발행
B19: 세부 견적 기준
B21: NO | D21: 중분류 | E21: 주요 기능 | H21: 예상 시작일 | I21: 예상 종료일 | J21: 월 비용 | K21: M/M | L21: 총합 | N21: _x0008_부가세
B22: 1 | D22: PMO | E22: - 프로젝트 세팅 - 프로젝트 통합 관리 | H22: 45778 | I22: 45900 | J22: 15000000 | K22: 0.4 | L22: =(I22 - H22)*J22*K22/30 -> 24400000 | N22: =L22*10% -> 2440000
B23: =B22+1 -> 2 | D23: 기획 | E23: - 비디오 서비스 기획 - 결제 서비스 기획 - 프로젝트 기획 | H23: 45778 | I23: 45808 | J23: 7500000 | K23: 1 | L23: =(I23 - H23)*J23*K23/30 -> 7500000 | N23: =L23*10% -> 750000
B24: =B23+1 -> 3 | D24: 디자인 | E24: - 앱 디자인 - 어드민 페이지 디자인 - 랜딩 페이지 디자인 | H24: 45778 | I24: 45838 | J24: 7500000 | K24: 1 | L24: =(I24 - H24)*J24*K24/30 -> 15000000 | N24: =L24*10% -> 1500000
B25: =B24+1 -> 4 | D25: 웹 프론트엔드 미들급 | E25: - 어드민 페이지 제작 - 랜딩 페이지 제작 | H25: 45809 | I25: 45869 | J25: 6000000 | K25: 1 | L25: =(I25 - H25)*J25*K25/30 -> 12000000 | N25: =L25*10% -> 1200000
B26: =B25+1 -> 5 | D26: 리액트 네이티브 시니어급 | E26: - 영상, 회차, 광고 개발 - 프로젝트 개발 총괄 | H26: 45778 | I26: 45900 | J26: 15000000 | K26: 1 | L26: =(I26 - H26)*J26*K26/30 -> 61000000 | N26: =L26*10% -> 6100000
B27: =B26+1 -> 6 | D27: 리액트 네이티브 미들급 | E27: - 결제, 유저 관리, 기타 기능 개발 - 베포 관리 | H27: 45778 | I27: 45900 | J27: 9000000 | K27: 1 | L27: =(I27 - H27)*J27*K27/30 -> 36600000 | N27: =L27*10% -> 3660000
B28: =B27+1 -> 7 | D28: 백엔드 시니어급 | E28: - 영상, 회차 광고 개발 - 서버 구축 | H28: 45778 | I28: 45900 | J28: 15000000 | K28: 1 | L28: =(I28 - H28)*J28*K28/30 -> 61000000 | N28: =L28*10% -> 6100000
B29: =B28+1 -> 8 | D29: 백엔드 미들급 | E29: - 결제, 유저 관리, 기타 기능 개발 | H29: 45778 | I29: 45900 | J29: 9000000 | K29: 1 | L29: =(I29 - H29)*J29*K29/30 -> 36600000 | N29: =L29*10% -> 3660000
D30: 소계 | K30: =SUM(K22:K29) -> 7.4 | L30: =sum(L22:L29) -> 254100000 | N30: =L30*10% -> 25410000
B33: 기타 | G33: 1. 파트너사에게 제공하는 할인 견적이므로, 외부 공유는 어려운 점 양해 부탁드립니다. 2. 세부 기능 명세가 러프하여, 다소 러프한 견적인 점을 감안해주시기 바랍니다.
C35: ⓒ 2025. PROTO INC. all rights reserved.

Sheet SET 투입 인력 및 비용
B1: 투입 인력
B3: NO | D3: 성함 | E3: 역할 | F3: 연차 | G3: 직접 인건비 (급여) | H3: 간접비 (4대보험료 등) | I3: 프로젝트 직접 경비 | J3: 월 실제 비용 | K3: 예상 업무 시간
B5: 1 | D5: 김지현 | E5: PMO(프로젝트 통합 관리) | F5: 12 | G5: 10000000 | H5: =G5*50% -> 5000000 | I5: 0 | J5: =(G5+H5+I5) -> 15000000
B6: 2 | D6: 김서호 | E6: PO(서비스 기획) / 미들급 | F6: 6 | G6: 5000000 | H6: =G6*50% -> 2500000 | I6: 0 | J6: =(G6+H6+I6) -> 7500000
B7: 3 | D7: 서윤 | E7: UIUX 디자이너 / 미들급 | F7: 6 | G7: 5000000 | H7: =G7*50% -> 2500000 | I7: 0 | J7: =(G7+H7+I7) -> 7500000
B8: 4 | D8: 현윤동 | E8: 웹 프론트엔드 개발자 / 미들급 | F8: 4 | G8: 4000000 | H8: =G8*50% -> 2000000 | I8: 0 | J8: =(G8+H8+I8) -> 6000000
B9: 5 | D9: 이준하 | E9: React Native 개발자 / 시니어급 | F9: 10 | G9: 10000000 | H9: =G9*50% -> 5000000 | I9: 0 | J9: =(G9+H9+I9) -> 15000000
B10: 6 | D10: 이기범 | E10: React Native 개발자 / 미들급 | F10: 6 | G10: 6000000 | H10: =G10*50% -> 3000000 | I10: 0 | J10: =(G10+H10+I10) -> 9000000
B11: 7 | D11: 최창기 | E11: 백엔드 개발자 / 시니어급 | F11: 12 | G11: 10000000 | H11: =G11*50% -> 5000000 | I11: 0 | J11: =(G11+H11+I11) -> 15000000
B12: 8 | D12: 조도흔 | E12: 백엔드 개발자 / 미들급 | F12: 7 | G12: 6000000 | H12: =G12*50% -> 3000000 | I12: 0 | J12: =(G12+H12+I12) -> 9000000
G13: 투입 인원 | H13: =COUNT(G1:G12) -> 8 | I13: 월 비용 총합 | J13: =sum(J5:J12) -> 84000000

Sheet SET 주요 휴일
A1: 2025 일본 공휴일
A2: 신정 | B2: 45658
A3: 성인의 날 | B3: 45670
A4: 건국기념일 | B4: 45699
A5: 천황 탄생일(주말) | B5: 45711
A6: 대체 공휴일(천황 탄생일) | B6: 45712
A7: 춘분의 날 | B7: 45736
A8: 쇼와의 날/골든위크 시작 | B8: 45776
A9: 골든위크 | B9: 45777
A10: 골든위크 | B10: 45778
A11: 골든위크 | B11: 45779
A12: 헌법 기념일/골든위크 | B12: 45780
A13: 녹색의 날(주말)/골든위크 | B13: 45781
... A26: 대체 공휴일(근로감사의 날) | B26: 45985
